Traceback (most recent call last):
  File "/home/janneae/miniconda3/envs/cns/lib/python3.8/site-packages/pandas/core/indexes/base.py", line 3621, in get_loc
    return self._engine.get_loc(casted_key)
  File "pandas/_libs/index.pyx", line 136, in pandas._libs.index.IndexEngine.get_loc
  File "pandas/_libs/index.pyx", line 163, in pandas._libs.index.IndexEngine.get_loc
  File "pandas/_libs/hashtable_class_helper.pxi", line 5198, in pandas._libs.hashtable.PyObjectHashTable.get_item
  File "pandas/_libs/hashtable_class_helper.pxi", line 5206, in pandas._libs.hashtable.PyObjectHashTable.get_item
KeyError: 'cancer_type'

The above exception was the direct cause of the following exception:

Traceback (most recent call last):
  File "sample_ascat.py", line 29, in <module>
    new_df = sample(df, args.nsamples)
  File "sample_ascat.py", line 14, in sample
    cancertypes = np.unique(df['cancer_type'])
  File "/home/janneae/miniconda3/envs/cns/lib/python3.8/site-packages/pandas/core/frame.py", line 3505, in __getitem__
    indexer = self.columns.get_loc(key)
  File "/home/janneae/miniconda3/envs/cns/lib/python3.8/site-packages/pandas/core/indexes/base.py", line 3623, in get_loc
    raise KeyError(key) from err
KeyError: 'cancer_type'
